<?xml version="1.0" encoding="utf-8" ?>
<!-- This URDF was automatically created by SolidWorks to URDF Exporter! Originally created by Stephen Brawner (brawner@gmail.com) 
     Commit Version: 1.6.0-4-g7f85cfe  Build Version: 1.6.7995.38578
     For more information, please see http://wiki.ros.org/sw_urdf_exporter -->
<robot name="robot_arm_description">
    <link name="base_link">
        <!-- <inertial>
      <origin
        xyz="-3.3841416465182E-05 -0.013188760389834 0.000535630045621771"
        rpy="0 0 0" />
      <mass
        value="0.0407434459292128" />
      <inertia
        ixx="1.14579171188663E-05"
        ixy="-1.0416027430262E-08"
        ixz="1.46302810170135E-09"
        iyy="6.24485768110896E-06"
        iyz="1.90943723184156E-07"
        izz="9.93757545826017E-06" />
    </inertial> -->
        <visual>
            <origin xyz="0 0 0" rpy="0 0 0" />
            <geometry>
                <mesh filename="package://robot_arm_description/meshes/base_link.STL" />
            </geometry>
            <material name="">
                <color rgba="0.792156862745098 0.819607843137255 0.933333333333333 1" />
            </material>
        </visual>
        <collision>
            <origin xyz="0 0 0" rpy="0 0 0" />
            <geometry>
                <mesh filename="package://robot_arm_description/meshes/base_link.STL" />
            </geometry>
        </collision>
        <inertial>
            <mass value="0.1" />
            <origin xyz="0 0 0" rpy="0 0 0" />
            <inertia ixx="0.03" iyy="0.03" izz="0.03" ixy="0.0" ixz="0.0" iyz="0.0" />
        </inertial>
    </link>
    <link name="link1">
        <inertial>
            <origin xyz="0.000504316355802528 0.0269920608293501 -0.000662636210924085" rpy="0 0 0" />
            <mass value="0.0462541915189553" />
            <inertia ixx="1.14052203125116E-05" ixy="1.18549320803042E-07" ixz="8.411767904232E-07" iyy="6.96980734371661E-06" iyz="-1.50099117128853E-07" izz="1.08126188486168E-05" />
        </inertial>
        <visual>
            <origin xyz="0 0 0" rpy="0 0 0" />
            <geometry>
                <mesh filename="package://robot_arm_description/meshes/link1.STL" />
            </geometry>
            <material name="">
                <color rgba="0.752941176470588 0.752941176470588 0.752941176470588 1" />
            </material>
        </visual>
        <collision>
            <origin xyz="0 0 0" rpy="0 0 0" />
            <geometry>
                <mesh filename="package://robot_arm_description/meshes/link1.STL" />
            </geometry>
        </collision>
    </link>
    <joint name="joint0" type="revolute">
        <origin xyz="0 0 0.021" rpy="1.5708 0 0.39793" />
        <parent link="base_link" />
        <child link="link1" />
        <axis xyz="0 1 0" />
        <limit lower="-1.57" upper="1.57" effort="1.8" velocity="10.15" />
    </joint>
    <link name="link2">
        <inertial>
            <origin xyz="0.0134244793418005 0.0511220631063565 0.00948725536107418" rpy="0 0 0" />
            <mass value="0.0263112092817441" />
            <inertia ixx="1.54469337921639E-05" ixy="-1.42388577313087E-06" ixz="3.51903716005461E-06" iyy="1.25247882109556E-05" iyz="-1.00628675452504E-06" izz="1.29545023279434E-05" />
        </inertial>
        <visual>
            <origin xyz="0 0 0" rpy="0 0 0" />
            <geometry>
                <mesh filename="package://robot_arm_description/meshes/link2.STL" />
            </geometry>
            <material name="">
                <color rgba="0.752941176470588 0.752941176470588 0.752941176470588 1" />
            </material>
        </visual>
        <collision>
            <origin xyz="0 0 0" rpy="0 0 0" />
            <geometry>
                <mesh filename="package://robot_arm_description/meshes/link2.STL" />
            </geometry>
        </collision>
    </link>
    <joint name="joint1" type="revolute">
        <origin xyz="0 0.0415 0" rpy="-0.061032 0.0026394 0.086413" />
        <parent link="link1" />
        <child link="link2" />
        <axis xyz="0.57714 0 -0.81665" />
        <limit lower="-1.57" upper="1.57" effort="1.8" velocity="10.15" />
    </joint>
    <link name="link3">
        <inertial>
            <origin xyz="-0.00252312533370934 0.0124355333369481 -0.000688191854294473" rpy="0 0 0" />
            <mass value="0.0430478213907683" />
            <inertia ixx="1.08596277287119E-05" ixy="9.19314478163503E-07" ixz="6.32416698791825E-07" iyy="6.51434171308305E-06" iyz="4.20003734263354E-07" izz="1.04881071660125E-05" />
        </inertial>
        <visual>
            <origin xyz="0 0 0" rpy="0 0 0" />
            <geometry>
                <mesh filename="package://robot_arm_description/meshes/link3.STL" />
            </geometry>
            <material name="">
                <color rgba="0.752941176470588 0.752941176470588 0.752941176470588 1" />
            </material>
        </visual>
        <collision>
            <origin xyz="0 0 0" rpy="0 0 0" />
            <geometry>
                <mesh filename="package://robot_arm_description/meshes/link3.STL" />
            </geometry>
        </collision>
    </link>
    <joint name="joint2" type="revolute">
        <origin xyz="0.026849 0.10224 0.018975" rpy="0.53725 0.23487 -0.80981" />
        <parent link="link2" />
        <child link="link3" />
        <axis xyz="0.57714 0 -0.81665" />
        <limit lower="-1.57" upper="1.57" effort="1.8" velocity="10.15" />
    </joint>
    <transmission name="trans_joint0">
        <type>transmission_interface/SimpleTransmission</type>
        <joint name="joint0">
            <hardwareInterface>hardware_interface/PositionJointInterface</hardwareInterface>
        </joint>
        <actuator name="joint0_motor">
            <hardwareInterface>hardware_interface/PositionJointInterface</hardwareInterface>
            <mechanicalReduction>1</mechanicalReduction>
        </actuator>
    </transmission>
    <transmission name="trans_joint1">
        <type>transmission_interface/SimpleTransmission</type>
        <joint name="joint1">
            <hardwareInterface>hardware_interface/PositionJointInterface</hardwareInterface>
        </joint>
        <actuator name="joint1_motor">
            <hardwareInterface>hardware_interface/PositionJointInterface</hardwareInterface>
            <mechanicalReduction>1</mechanicalReduction>
        </actuator>
    </transmission>
    <transmission name="trans_joint2">
        <type>transmission_interface/SimpleTransmission</type>
        <joint name="joint2">
            <hardwareInterface>hardware_interface/PositionJointInterface</hardwareInterface>
        </joint>
        <actuator name="joint2_motor">
            <hardwareInterface>hardware_interface/PositionJointInterface</hardwareInterface>
            <mechanicalReduction>1</mechanicalReduction>
        </actuator>
    </transmission>
    <gazebo>
        <plugin name="gazebo_ros_control">
            <robotNamespace>/</robotNamespace>
        </plugin>
    </gazebo>
</robot>

