<?xml version="1.0" encoding="utf-8"?>
<!-- This URDF was automatically created by SolidWorks to URDF Exporter! Originally created by Stephen Brawner (brawner@gmail.com) 
     Commit Version: 1.6.0-4-g7f85cfe  Build Version: 1.6.7995.38578
     For more information, please see http://wiki.ros.org/sw_urdf_exporter -->
<robot
  name="robot_arm_description_urdfv6">
  <link
    name="base_link">
    <inertial>
      <origin
        xyz="-1.07538454317689E-05 -0.0117775627710086 0.0125372666056596"
        rpy="0 0 0" />
      <mass
        value="0.121294608559114" />
      <inertia
        ixx="5.94662409992812E-05"
        ixy="1.4986009441338E-09"
        ixz="1.03128418541428E-08"
        iyy="0.000106542660004419"
        iyz="-5.79668025744953E-07"
        izz="5.77712338446558E-05" />
    </inertial>
    <visual>
      <origin
        xyz="0 0 0"
        rpy="0 0 0" />
      <geometry>
        <mesh
          filename="package://robot_arm_description_urdfv6/meshes/base_link.STL" />
      </geometry>
      <material
        name="">
        <color
          rgba="0.752941176470588 0.752941176470588 0.752941176470588 1" />
      </material>
    </visual>
    <collision>
      <origin
        xyz="0 0 0"
        rpy="0 0 0" />
      <geometry>
        <mesh
          filename="package://robot_arm_description_urdfv6/meshes/base_link.STL" />
      </geometry>
    </collision>
  </link>
  <link
    name="link1">
    <inertial>
      <origin
        xyz="2.94146431116214E-05 0.0269920612131043 -0.00083220015454471"
        rpy="0 0 0" />
      <mass
        value="0.0462541920676047" />
      <inertia
        ixx="1.20007548213709E-05"
        ixy="1.01847426351156E-08"
        ixz="1.49860094413093E-09"
        iyy="6.9698072517776E-06"
        iyz="-1.90997297407253E-07"
        izz="1.02170843156605E-05" />
    </inertial>
    <visual>
      <origin
        xyz="0 0 0"
        rpy="0 0 0" />
      <geometry>
        <mesh
          filename="package://robot_arm_description_urdfv6/meshes/link1.STL" />
      </geometry>
      <material
        name="">
        <color
          rgba="0.752941176470588 0.752941176470588 0.752941176470588 1" />
      </material>
    </visual>
    <collision>
      <origin
        xyz="0 0 0"
        rpy="0 0 0" />
      <geometry>
        <mesh
          filename="package://robot_arm_description_urdfv6/meshes/link1.STL" />
      </geometry>
    </collision>
  </link>
  <joint
    name="joint0"
    type="revolute">
    <origin
      xyz="0 0 0.021"
      rpy="1.5708 0 0" />
    <parent
      link="base_link" />
    <child
      link="link1" />
    <axis
      xyz="0 1 0" />
    <limit
      lower="-2.61"
      upper="2.61"
      effort="0"
      velocity="0" />
  </joint>
  <link
    name="link2">
    <inertial>
      <origin
        xyz="2.28486579373317E-06 0.026 -1.88579241854202E-16"
        rpy="0 0 0" />
      <mass
        value="0.0145830072313276" />
      <inertia
        ixx="6.47120046834471E-06"
        ixy="4.28350310331757E-22"
        ixz="1.04955163724937E-22"
        iyy="5.75321998222016E-06"
        iyz="-1.38527695901273E-17"
        izz="2.45168199477264E-06" />
    </inertial>
    <visual>
      <origin
        xyz="0 0 0"
        rpy="0 0 0" />
      <geometry>
        <mesh
          filename="package://robot_arm_description_urdfv6/meshes/link2.STL" />
      </geometry>
      <material
        name="">
        <color
          rgba="0.752941176470588 0.752941176470588 0.752941176470588 1" />
      </material>
    </visual>
    <collision>
      <origin
        xyz="0 0 0"
        rpy="0 0 0" />
      <geometry>
        <mesh
          filename="package://robot_arm_description_urdfv6/meshes/link2.STL" />
      </geometry>
    </collision>
  </link>
  <joint
    name="joint1"
    type="revolute">
    <origin
      xyz="0 0.0415 0"
      rpy="0 0 0" />
    <parent
      link="link1" />
    <child
      link="link2" />
    <axis
      xyz="0 0 1" />
    <limit
      lower="-2.61"
      upper="2.61"
      effort="0"
      velocity="0" />
  </joint>
  <link
    name="link3">
    <inertial>
      <origin
        xyz="-2.36223749316902E-05 0.019670540731528 -0.000718876565097297"
        rpy="0 0 0" />
      <mass
        value="0.0535456956833657" />
      <inertia
        ixx="1.5236355055544E-05"
        ixy="1.02840047357545E-08"
        ixz="-1.49860092852113E-09"
        iyy="9.8464172428884E-06"
        iyz="1.90997297414243E-07"
        izz="1.14429253130468E-05" />
    </inertial>
    <visual>
      <origin
        xyz="0 0 0"
        rpy="0 0 0" />
      <geometry>
        <mesh
          filename="package://robot_arm_description_urdfv6/meshes/link3.STL" />
      </geometry>
      <material
        name="">
        <color
          rgba="0.752941176470588 0.752941176470588 0.752941176470588 1" />
      </material>
    </visual>
    <collision>
      <origin
        xyz="0 0 0"
        rpy="0 0 0" />
      <geometry>
        <mesh
          filename="package://robot_arm_description_urdfv6/meshes/link3.STL" />
      </geometry>
    </collision>
  </link>
  <joint
    name="joint2"
    type="revolute">
    <origin
      xyz="0 0.052 0"
      rpy="-3.1416 0 -3.1416" />
    <parent
      link="link2" />
    <child
      link="link3" />
    <axis
      xyz="0 0 1" />
    <limit
      lower="-2.61"
      upper="2.61"
      effort="0"
      velocity="0" />
  </joint>
  <link
    name="link4">
    <inertial>
      <origin
        xyz="2.69860165410205E-05 0.0145079387868957 0.000832200154544751"
        rpy="0 0 0" />
      <mass
        value="0.0462541920676045" />
      <inertia
        ixx="1.20007548213709E-05"
        ixy="-1.04409410731774E-08"
        ixz="-1.49860094413215E-09"
        iyy="6.96980725177758E-06"
        iyz="-1.90997297407222E-07"
        izz="1.02170843156605E-05" />
    </inertial>
    <visual>
      <origin
        xyz="0 0 0"
        rpy="0 0 0" />
      <geometry>
        <mesh
          filename="package://robot_arm_description_urdfv6/meshes/link4.STL" />
      </geometry>
      <material
        name="">
        <color
          rgba="0.752941176470588 0.752941176470588 0.752941176470588 1" />
      </material>
    </visual>
    <collision>
      <origin
        xyz="0 0 0"
        rpy="0 0 0" />
      <geometry>
        <mesh
          filename="package://robot_arm_description_urdfv6/meshes/link4.STL" />
      </geometry>
    </collision>
  </link>
  <joint
    name="joint3"
    type="revolute">
    <origin
      xyz="0 0.0675 0"
      rpy="0 0 0" />
    <parent
      link="link3" />
    <child
      link="link4" />
    <axis
      xyz="0 0 -1" />
    <limit
      lower="-2.61"
      upper="2.61"
      effort="0"
      velocity="0" />
  </joint>
  <link
    name="link5">
    <inertial>
      <origin
        xyz="-0.0348900522484704 0.0327211837420749 0.020349717936593"
        rpy="0 0 0" />
      <mass
        value="0.140900258362422" />
      <inertia
        ixx="5.94784854048947E-05"
        ixy="2.00927826545369E-07"
        ixz="-2.011820400424E-07"
        iyy="5.26566243243145E-05"
        iyz="1.01616894838829E-06"
        izz="2.33466420632803E-05" />
    </inertial>
    <visual>
      <origin
        xyz="0 0 0"
        rpy="0 0 0" />
      <geometry>
        <mesh
          filename="package://robot_arm_description_urdfv6/meshes/link5.STL" />
      </geometry>
      <material
        name="">
        <color
          rgba="0.752941176470588 0.752941176470588 0.752941176470588 1" />
      </material>
    </visual>
    <collision>
      <origin
        xyz="0 0 0"
        rpy="0 0 0" />
      <geometry>
        <mesh
          filename="package://robot_arm_description_urdfv6/meshes/link5.STL" />
      </geometry>
    </collision>
  </link>
  <joint
    name="joint4"
    type="revolute">
    <origin
      xyz="0 0.0405 0"
      rpy="-3.1416 0 -3.1416" />
    <parent
      link="link4" />
    <child
      link="link5" />
    <axis
      xyz="0 -1 0" />
    <limit
      lower="-2.61"
      upper="2.61"
      effort="0"
      velocity="0" />
  </joint>
  <!-- <link
    name="endposition">
    <inertial>
      <origin
        xyz="-3.46944695195361E-17 -0.0216087961436311 0.00349267226366691"
        rpy="0 0 0" />
      <mass
        value="0.00601954229095053" />
      <inertia
        ixx="3.853040967078E-06"
        ixy="-3.88108084128754E-21"
        ixz="-8.2890185036032E-23"
        iyy="1.32172840672189E-07"
        iyz="-6.38834117868935E-08"
        izz="3.93224766260515E-06" />
    </inertial>
    <visual>
      <origin
        xyz="0 0 0"
        rpy="0 0 0" />
      <geometry>
        <mesh
          filename="package://robot_arm_description_urdfv6/meshes/endposition.STL" />
      </geometry>
      <material
        name="">
        <color
          rgba="0.792156862745098 0.819607843137255 0.933333333333333 1" />
      </material>
    </visual>
    <collision>
      <origin
        xyz="0 0 0"
        rpy="0 0 0" />
      <geometry>
        <mesh
          filename="package://robot_arm_description_urdfv6/meshes/endposition.STL" />
      </geometry>
    </collision>
  </link> -->
  <!-- <joint
    name="fixjoint"
    type="fixed">
    <origin
      xyz="-0.069 0.022 0.0285"
      rpy="3.1416 1.5708 0" />
    <parent
      link="link5" />
    <child
      link="endposition" />
    <axis
      xyz="0 0 0" />
  </joint> -->
  <link
    name="gripperindication">
    <inertial>
      <origin
        xyz="1.67227343084164E-15 -0.00438007948641138 -1.38777878078145E-16"
        rpy="0 0 0" />
      <mass
        value="0.00336712206554558" />
      <inertia
        ixx="1.09965259115178E-07"
        ixy="-1.22673275657772E-22"
        ixz="2.31373380475812E-22"
        iyy="3.27204441176996E-07"
        iyz="-3.86824446185331E-22"
        izz="2.55595049786693E-07" />
    </inertial>
    <visual>
      <origin
        xyz="0 0 0"
        rpy="0 0 0" />
      <geometry>
        <mesh
          filename="package://robot_arm_description_urdfv6/meshes/gripperindication.STL" />
      </geometry>
      <material
        name="">
        <color
          rgba="0.792156862745098 0.819607843137255 0.933333333333333 1" />
      </material>
    </visual>
    <collision>
      <origin
        xyz="0 0 0"
        rpy="0 0 0" />
      <geometry>
        <mesh
          filename="package://robot_arm_description_urdfv6/meshes/gripperindication.STL" />
      </geometry>
    </collision>
  </link>
  <joint
    name="joint5"
    type="revolute">
    <origin
      xyz="-0.061 0.022 0.0285"
      rpy="1.5708 1.5708 0" />
    <parent
      link="link5" />
    <child
      link="gripperindication" />
    <axis
      xyz="0 -1 0" />
    <limit
      lower="-2.61"
      upper="0"
      effort="0"
      velocity="0" />
  </joint>


  <link
    name="grip_point">
  </link>
  <joint
    name="grip_fixed"
    type="fixed">
    <origin
      xyz="-0.060 0.097 0.0285"
      rpy="1.5708 1.5708 0" />
    <parent
      link="link5" />
    <child
      link="grip_point" />
  </joint>





  <link
    name="world">
  </link>
  <joint
    name="fixed_joint"
    type="fixed">
    <origin
      xyz="0 0 0.026"
      rpy="0 0 0" />
    <parent
      link="world" />
    <child
      link="base_link" />
  </joint>
</robot>